Workbook

Sheet Instrucciones
B1: Plantilla E1 · Catálogo de casos de prueba y matriz de trazabilidad (VERSIÓN EN BLANCO)
B2: Pruebas de Software · Proyecto Nuclear · Sistema web de predicción de demanda · Corte 1 (vence el 23/10/2026)
B4: QUÉ ES ESTE ARCHIVO
B5: Un solo libro de Excel que sirve para el Anexo A del Plan maestro (catálogo de casos) y para el entregable E1.2 (matriz de trazabilidad). Esta es la versión EN BLANCO: las fórmulas, listas y validaciones ya funcionan; solo escribe tus datos. Abajo hay un ejemplo de cómo se llena una fila de cada hoja.
B7: HOJAS
B8: Requisitos → lista de requisitos del backlog. Todo parte de aquí.
B9: Catalogo → un caso de prueba por fila (ID, requisito, técnica, datos de entrada, resultado esperado, tolerancia…).
B10: Verificacion → compara el valor del sistema con el valor de referencia de Producción y calcula APROBADO / FALLIDO con la tolerancia.
B11: Calculo_Referencia → el cálculo independiente en Excel (promedio móvil, suavización exponencial, regresión, MAD, MSE, MAPE). Es lo que hace Producción.
B12: Matriz → trazabilidad: qué casos verifican cada requisito. Detecta requisitos sin cobertura.
B13: Cobertura → revisa tu entrega: % de requisitos cubiertos, mínimo de casos, casos huérfanos. Se calcula solo.
B14: Riesgos → matriz de riesgos (exposición = probabilidad × impacto) para priorizar las pruebas.
... B40: Riesgos → R-01 | MAPE mal calculado cuando la demanda real es 0 | Pronóstico | Producto | probabilidad 4 | impacto 5 → exposición 20, nivel Alto

Sheet Requisitos
A1: Requisitos del sistema de predicción de demanda
A2: Aquí listas los requisitos del backlog (levantados con Producción). La Matriz y la Cobertura se alimentan de esta hoja. Celdas azules = datos que tú escribes.
A4: ID requisito | B4: Descripción | C4: Módulo | D4: Tipo | E4: Prioridad
A5: RF-01 | B5: Iniciar y cerrar sesión con credenciales; la sesión expira por inactividad | C5: Autenticación y roles | D5: Funcional | E5: Alta
A6: RF-02 | B6: Gestionar usuarios: crear, editar, desactivar y asignar uno de los cuatro roles | C6: Autenticación y roles | D6: Funcional | E6: Alta
A7: RF-03 | B7: Controlar el acceso por rol a pantallas y endpoints (403 sin permiso) | C7: Autenticación y roles | D7: Funcional | E7: Alta
A8: RF-04 | B8: CRUD de los 3 productos con código, nombre, categoría y unidad | C8: Gestión de datos | D8: Funcional | E8: Alta
A9: RF-05 | B9: Registrar manualmente producción y demanda por producto y mes, sin duplicar producto-período | C9: Gestión de datos | D9: Funcional | E9: Alta
A10: RF-06 | B10: Cargar el histórico desde CSV o Excel (24 períodos) informando filas cargadas y rechazadas | C10: Gestión de datos | D10: Funcional | E10: Alta
A11: RF-07 | B11: Detectar atípicos y faltantes y permitir corregirlos o imputarlos conservando el original | C11: Gestión de datos | D11: Funcional | E11: Media
A12: RF-08 | B12: Registrar la capacidad disponible por centro de trabajo y período | C12: Gestión de datos | D12: Funcional | E12: Media
A13: RF-09 | B13: Visualizar el histórico en tabla y gráfico de líneas con filtros por producto y rango | C13: Gestión de datos | D13: Funcional | E13: Alta
A14: RF-10 | B14: Configurar parámetros por modelo (n, pesos, α, β, horizonte) validando rangos | C14: Pronóstico | D14: Funcional | E14: Alta
A15: RF-11 | B15: Ejecutar promedio móvil simple | C15: Pronóstico | D15: Funcional | E15: Alta
... A45: RNF-16 | B45: Documentación: un ADR por decisión arquitectónica relevante | C45: Transversal | D45: No funcional | E45: Baja

Sheet Calculo Produccion
B1: EL-06 | C1: Electrodos Adhesivos Cuadrados CM5050 | M1: T-07 | N1: Intensity Twin Stim III Tens/Ems | X1: T-01 | Y1: Tens Analogo 3000
B2: Periodo | C2: Cantidad | D2: Pt n=2 | E2: [Et]= n=2 | F2: [Et]/Dt | G2: Pt n=3 | H2: [Et]= n=3 | I2: [Et]/Dt | M2: Periodo | N2: Cantidad | O2: Pt n=2 | P2: [Et]= n=2 | Q2: [Et]/Dt | R2: Pt n=3 | S2: [Et]= n=3 | T2: [Et]/Dt | X2: Periodo | Y2: Cantidad | Z2: Pt n=2 | AA2: [Et]= n=2 | AB2: [Et]/Dt | AC2: Pt n=3 | AD2: [Et]= n=3 | AE2: [Et]/Dt
A3: 2024 | B3: Enero | C3: 1679 | D3: / | E3: / | F3: / | G3: / | H3: / | I3: / | L3: 2024 | M3: Enero | N3: 129 | O3: / | P3: / | Q3: / | R3: / | S3: / | T3: / | W3: 2024 | X3: Enero | Y3: 121 | Z3: / | AA3: / | AB3: / | AC3: / | AD3: / | AE3: /
B4: Febrero | C4: 1984 | D4: / | E4: / | F4: / | G4: / | H4: / | I4: / | M4: Febrero | N4: 97 | O4: / | P4: / | Q4: / | R4: / | S4: / | T4: / | X4: Febrero | Y4: 94 | Z4: / | AA4: / | AB4: / | AC4: / | AD4: / | AE4: /
B5: Marzo | C5: 868 | D5: 1831.5 | E5: 963.5 | F5: 1.11 | G5: / | H5: / | I5: / | M5: Marzo | N5: 83 | O5: 113 | P5: 30 | Q5: 0.3614 | R5: / | S5: / | T5: / | X5: Marzo | Y5: 93 | Z5: 107.5 | AA5: 14.5 | AB5: 0.1559 | AC5: / | AD5: / | AE5: /
B6: Abril | C6: 1419 | D6: 1426 | E6: 7 | F6: 0.0049 | G6: 1510.33 | H6: 91.3 | I6: 0.0644 | M6: Abril | N6: 157 | O6: 90 | P6: 67 | Q6: 0.4268 | R6: 103 | S6: 54 | T6: 0.3439 | X6: Abril | Y6: 104 | Z6: 94 | AA6: 10.5 | AB6: 0.101 | AC6: 102.67 | AD6: 1.3 | AE6: 0.0128
B7: Mayo | C7: 861 | D7: 1144 | E7: 282.5 | F7: 0.3281 | G7: 1423.67 | H7: 562.7 | I7: 0.6535 | M7: Mayo | N7: 112 | O7: 120 | P7: 8 | Q7: 0.0714 | R7: 112.33 | S7: 0.3 | T7: 0.003 | X7: Mayo | Y7: 58 | Z7: 99 | AA7: 40.5 | AB7: 0.6983 | AC7: 97 | AD7: 39 | AE7: 0.6724
B8: Junio | C8: 827 | D8: 1140 | E8: 313 | F8: 0.3785 | G8: 1049.33 | H8: 222.3 | I8: 0.2688 | M8: Junio | N8: 73 | O8: 135 | P8: 61.5 | Q8: 0.8425 | R8: 117.33 | S8: 44.3 | T8: 0.6073 | X8: Junio | Y8: 102 | Z8: 81 | AA8: 21 | AB8: 0.2059 | AC8: 85 | AD8: 17 | AE8: 0.1667
B9: Julio | C9: 860 | D9: 844 | E9: 16 | F9: 0.0186 | G9: 1035.67 | H9: 175.7 | I9: 0.2043 | M9: Julio | N9: 79 | O9: 93 | P9: 13.5 | Q9: 0.1709 | R9: 114 | S9: 35 | T9: 0.443 | X9: Julio | Y9: 121 | Z9: 80 | AA9: 41 | AB9: 0.3388 | AC9: 88 | AD9: 33 | AE9: 0.2727
B10: Agosto | C10: 1721 | D10: 844 | E10: 877.5 | F10: 0.5099 | G10: 849.33 | H10: 871.7 | I10: 0.5065 | M10: Agosto | N10: 107 | O10: 76 | P10: 31 | Q10: 0.2897 | R10: 88 | S10: 19 | T10: 0.1776 | X10: Agosto | Y10: 96 | Z10: 112 | AA10: 15.5 | AB10: 0.1615 | AC10: 93.67 | AD10: 2.3 | AE10: 0.0243
B11: Septiembre | C11: 1329 | D11: 1291 | E11: 38.5 | F11: 0.029 | G11: 1136 | H11: 193 | I11: 0.1452 | M11: Septiembre | N11: 73 | O11: 93 | P11: 20 | Q11: 0.274 | R11: 86.33 | S11: 13.3 | T11: 0.1826 | X11: Septiembre | Y11: 63 | Z11: 109 | AA11: 45.5 | AB11: 0.7222 | AC11: 106.33 | AD11: 43.3 | AE11: 0.6878
B12: Octubre | C12: 957 | D12: 1525 | E12: 568 | F12: 0.5935 | G12: 1303.33 | H12: 346.3 | I12: 0.3619 | M12: Octubre | N12: 141 | O12: 90 | P12: 51 | Q12: 0.3617 | R12: 86.33 | S12: 54.7 | T12: 0.3877 | X12: Octubre | Y12: 97 | Z12: 80 | AA12: 17.5 | AB12: 0.1804 | AC12: 93.33 | AD12: 3.7 | AE12: 0.0378
B13: Noviembre | C13: 1024 | D13: 1143 | E13: 119 | F13: 0.1162 | G13: 1335.67 | H13: 311.7 | I13: 0.3044 | M13: Noviembre | N13: 83 | O13: 107 | P13: 24 | Q13: 0.2892 | R13: 107 | S13: 24 | T13: 0.2892 | X13: Noviembre | Y13: 101 | Z13: 80 | AA13: 21 | AB13: 0.2079 | AC13: 85.33 | AD13: 15.7 | AE13: 0.1551
B14: Diciembre | C14: 1218 | D14: 991 | E14: 227.5 | F14: 0.1868 | G14: 1103.33 | H14: 114.7 | I14: 0.0941 | M14: Diciembre | N14: 97 | O14: 112 | P14: 15 | Q14: 0.1546 | R14: 99 | S14: 2 | T14: 0.0206 | X14: Diciembre | Y14: 69 | Z14: 99 | AA14: 30 | AB14: 0.4348 | AC14: 87 | AD14: 18 | AE14: 0.2609
A15: 2025 | B15: Enero | C15: 950 | D15: 1121 | E15: 171 | F15: 0.18 | G15: 1066.33 | H15: 116.3 | I15: 0.1225 | L15: 2025 | M15: Enero | N15: 138 | O15: 90 | P15: 48 | Q15: 0.3478 | R15: 107 | S15: 31 | T15: 0.2246 | W15: 2025 | X15: Enero | Y15: 104 | Z15: 85 | AA15: 19 | AB15: 0.1827 | AC15: 89 | AD15: 15 | AE15: 0.1442
B16: Febrero | C16: 919 | D16: 1084 | E16: 165 | F16: 0.1795 | G16: 1064 | H16: 145 | I16: 0.1578 | M16: Febrero | N16: 116 | O16: 118 | P16: 1.5 | Q16: 0.0129 | R16: 106 | S16: 10 | T16: 0.0862 | X16: Febrero | Y16: 77 | Z16: 87 | AA16: 9.5 | AB16: 0.1234 | AC16: 91.33 | AD16: 14.3 | AE16: 0.1861
B17: Marzo | C17: 1058 | D17: 935 | E17: 123.5 | F17: 0.1167 | G17: 1029 | H17: 29 | I17: 0.0274 | M17: Marzo | N17: 70 | O17: 127 | P17: 57 | Q17: 0.8143 | R17: 117 | S17: 47 | T17: 0.6714 | X17: Marzo | Y17: 44 | Z17: 91 | AA17: 46.5 | AB17: 1.0568 | AC17: 83.33 | AD17: 39.3 | AE17: 0.8939
B18: Abril | C18: 903 | D18: 989 | E18: 85.5 | F18: 0.0947 | G18: 975.67 | H18: 72.7 | I18: 0.0805 | M18: Abril | N18: 107 | O18: 93 | P18: 14 | Q18: 0.1308 | R18: 108 | S18: 1 | T18: 0.0093 | X18: Abril | Y18: 36 | Z18: 61 | AA18: 24.5 | AB18: 0.6806 | AC18: 75 | AD18: 39 | AE18: 1.0833
B19: Mayo | C19: 1629 | D19: 981 | E19: 648.5 | F19: 0.3981 | G19: 960 | H19: 669 | I19: 0.4107 | M19: Mayo | N19: 118 | O19: 89 | P19: 29.5 | Q19: 0.25 | R19: 97.67 | S19: 20.3 | T19: 0.1723 | X19: Mayo | Y19: 100 | Z19: 40 | AA19: 60 | AB19: 0.6 | AC19: 52.33 | AD19: 47.7 | AE19: 0.4767
B20: Junio | C20: 1845 | D20: 1266 | E20: 579 | F20: 0.3138 | G20: 1196.67 | H20: 648.3 | I20: 0.3514 | M20: Junio | N20: 89 | O20: 113 | P20: 23.5 | Q20: 0.264 | R20: 98.33 | S20: 9.3 | T20: 0.1049 | X20: Junio | Y20: 69 | Z20: 68 | AA20: 1 | AB20: 0.0145 | AC20: 60 | AD20: 9 | AE20: 0.1304
B21: Julio | C21: 1503 | D21: 1737 | E21: 234 | F21: 0.1557 | G21: 1459 | H21: 44 | I21: 0.0293 | M21: Julio | N21: 90 | O21: 104 | P21: 13.5 | Q21: 0.15 | R21: 104.67 | S21: 14.7 | T21: 0.163 | X21: Julio | Y21: 71 | Z21: 85 | AA21: 13.5 | AB21: 0.1901 | AC21: 68.33 | AD21: 2.7 | AE21: 0.0376
B22: Agosto | C22: 1373 | D22: 1674 | E22: 301 | F22: 0.2192 | G22: 1659 | H22: 286 | I22: 0.2083 | M22: Agosto | N22: 20 | O22: 90 | P22: 69.5 | Q22: 3.475 | R22: 99 | S22: 79 | T22: 3.95 | X22: Agosto | Y22: 74 | Z22: 70 | AA22: 4 | AB22: 0.0541 | AC22: 80 | AD22: 6 | AE22: 0.0811
B23: Septiembre | C23: 2313 | D23: 1438 | E23: 875 | F23: 0.3783 | G23: 1573.67 | H23: 739.3 | I23: 0.3196 | M23: Septiembre | N23: 189 | O23: 55 | P23: 134 | Q23: 0.709 | R23: 66.33 | S23: 122.7 | T23: 0.649 | X23: Septiembre | Y23: 155 | Z23: 73 | AA23: 82.5 | AB23: 0.5323 | AC23: 71.33 | AD23: 83.7 | AE23: 0.5398
B24: Octubre | C24: 1601 | D24: 1843 | E24: 242 | F24: 0.1512 | G24: 1729.67 | H24: 128.7 | I24: 0.0804 | M24: Octubre | N24: 151 | O24: 105 | P24: 46.5 | Q24: 0.3079 | R24: 99.67 | S24: 51.3 | T24: 0.34 | X24: Octubre | Y24: 110 | Z24: 115 | AA24: 4.5 | AB24: 0.0409 | AC24: 100 | AD24: 10 | AE24: 0.0909
B25: Noviembre | C25: 1288 | D25: 1957 | E25: 669 | F25: 0.5194 | G25: 1762.33 | H25: 474.3 | I25: 0.3683 | M25: Noviembre | N25: 78 | O25: 170 | P25: 92 | Q25: 1.1795 | R25: 120 | S25: 42 | T25: 0.5385 | X25: Noviembre | Y25: 141 | Z25: 133 | AA25: 8.5 | AB25: 0.0603 | AC25: 113 | AD25: 28 | AE25: 0.1986
B26: Diciembre | C26: 982 | D26: 1445 | E26: 462.5 | F26: 0.471 | G26: 1734 | H26: 752 | I26: 0.7658 | M26: Diciembre | N26: 174 | O26: 115 | P26: 59.5 | Q26: 0.342 | R26: 139.33 | S26: 34.7 | T26: 0.1992 | X26: Diciembre | Y26: 126 | Z26: 126 | AA26: 0.5 | AB26: 0.004 | AC26: 135.33 | AD26: 9.3 | AE26: 0.0741
A27: 2026 | B27: Enero | C27: 1537 | D27: 1135 | E27: 402 | F27: 0.2615 | G27: 1290.33 | H27: 246.7 | I27: 0.1605 | L27: 2026 | M27: Enero | N27: 150 | O27: 126 | P27: 24 | Q27: 0.16 | R27: 134.33 | S27: 15.7 | T27: 0.1044 | W27: 2026 | X27: Enero | Y27: 136 | Z27: 134 | AA27: 2.5 | AB27: 0.0184 | AC27: 125.67 | AD27: 10.3 | AE27: 0.076
B28: Febrero | C28: 1240 | D28: 1260 | E28: 19.5 | F28: 0.0157 | G28: 1269 | H28: 29 | I28: 0.0234 | M28: Febrero | N28: 140 | O28: 162 | P28: 22 | Q28: 0.1571 | R28: 134 | S28: 6 | T28: 0.0429 | X28: Febrero | Y28: 178 | Z28: 131 | AA28: 47 | AB28: 0.264 | AC28: 134.33 | AD28: 43.7 | AE28: 0.2453
B29: Marzo | C29: 1613 | D29: 1389 | E29: 224.5 | F29: 0.1392 | G29: 1253 | H29: 360 | I29: 0.2232 | M29: Marzo | N29: 142 | O29: 145 | P29: 3 | Q29: 0.0211 | R29: 154.67 | S29: 12.7 | T29: 0.0892 | X29: Marzo | Y29: 153 | Z29: 157 | AA29: 4 | AB29: 0.0261 | AC29: 146.67 | AD29: 6.3 | AE29: 0.0414
B30: Abril | C30: 2859 | D30: 1427 | E30: 1432.5 | F30: 0.501 | G30: 1463.33 | H30: 1395.7 | I30: 0.4882 | M30: Abril | N30: 196 | O30: 141 | P30: 55 | Q30: 0.2806 | R30: 144 | S30: 52 | T30: 0.2653 | X30: Abril | Y30: 175 | Z30: 166 | AA30: 9.5 | AB30: 0.0543 | AC30: 155.67 | AD30: 19.3 | AE30: 0.1105
B31: Mayo | C31: 1401 | D31: 2236 | E31: 835 | F31: 0.596 | G31: 1904 | H31: 503 | I31: 0.359 | M31: Mayo | N31: 192 | O31: 169 | P31: 23 | Q31: 0.1198 | R31: 159.33 | S31: 32.7 | T31: 0.1701 | X31: Mayo | Y31: 119 | Z31: 164 | AA31: 45 | AB31: 0.3782 | AC31: 168.67 | AD31: 49.7 | AE31: 0.4174
B32: Junio | C32: 1148 | D32: 2130 | E32: 982 | F32: 0.8554 | G32: 1957.67 | H32: 809.7 | I32: 0.7053 | M32: Junio | N32: 163 | O32: 194 | P32: 31 | Q32: 0.1902 | R32: 176.67 | S32: 13.7 | T32: 0.0838 | X32: Junio | Y32: 133 | Z32: 147 | AA32: 14 | AB32: 0.1053 | AC32: 149 | AD32: 16 | AE32: 0.1203
B33: Julio | C33: 2157 | D33: 1275 | E33: 882.5 | F33: 0.4091 | G33: 1802.67 | H33: 354.3 | I33: 0.1643 | M33: Julio | N33: 215 | O33: 178 | P33: 37.5 | Q33: 0.1744 | R33: 183.67 | S33: 31.3 | T33: 0.1457 | X33: Julio | Y33: 221 | Z33: 126 | AA33: 95 | AB33: 0.4299 | AC33: 142.33 | AD33: 78.7 | AE33: 0.356
B34: Agosto | C34: 1611 | D34: 1653 | E34: 41.5 | F34: 0.0258 | G34: 1568.67 | H34: 42.3 | I34: 0.0263 | M34: Agosto | N34: 147 | O34: 189 | P34: 42 | Q34: 0.2857 | R34: 190 | S34: 43 | T34: 0.2925 | X34: Agosto | Y34: 89 | Z34: 177 | AA34: 88 | AB34: 0.9888 | AC34: 157.67 | AD34: 68.7 | AE34: 0.7715
B35: Septiembre | C35: 1251 | D35: 1884 | E35: 633 | F35: 0.506 | G35: 1638.67 | H35: 387.7 | I35: 0.3099 | M35: Septiembre | N35: 162 | O35: 181 | P35: 19 | Q35: 0.1173 | R35: 175 | S35: 13 | T35: 0.0802 | X35: Septiembre | Y35: 159 | Z35: 155 | AA35: 4 | AB35: 0.0252 | AC35: 147.67 | AD35: 11.3 | AE35: 0.0713
B36: Octubre | C36: 1496 | D36: 1431 | E36: 65 | F36: 0.0434 | G36: 1673 | H36: 177 | I36: 0.1183 | M36: Octubre | N36: 121 | O36: 155 | P36: 33.5 | Q36: 0.2769 | R36: 174.67 | S36: 53.7 | T36: 0.4435 | X36: Octubre | Y36: 70 | Z36: 124 | AA36: 54 | AB36: 0.7714 | AC36: 156.33 | AD36: 86.3 | AE36: 1.2333
E37: MAD = | F37: 421.4375 | H37: MAD = | I37: 364.49462 | P37: MAD = | Q37: 37.484375 | S37: MAD = | T37: 31.72043 | AA37: MAD = | AB37: 27.9375 | AD37: MAD = | AE37: 27.989247
E38: MAPE = | F38: 0.3064 | H38: MAPE = | I38: 0.2614 | P38: MAPE = | Q38: 0.4065 | S38: MAPE = | T38: 0.3639 | AA38: MAPE = | AB38: 0.3065 | AD38: MAPE = | AE38: 0.3119

Sheet Calculo_Referencia
A1: Referencia independiente · CAF-500 · serie sintética de 24 meses
A2: Datos diseñados para prueba, no registros reales. Cargar los mismos 24 valores en el sistema; Producción debe validar convenciones y tolerancia.
A4: t | B4: Demanda real | C4: PMS(3) | D4: PMP(3) | E4: SES | F4: Nivel Holt | G4: Tendencia Holt | H4: Holt ajustado | I4: Regresión ajustada | J4: Error PMS | K4: |Error| | L4: Error² | M4: APE (%) | Q4: Parámetros | R4: Valor
A5: 1 | B5: 4200 | F5: =B5 -> 4200 | G5: =B6-B5 -> 110 | I5: =INTERCEPT($B$5:$B$28,$A$5:$A$28)+SLOPE($B$5:$B$28,$A$5:$A$28)*A5 -> 4433.1833 | Q5: Peso reciente | R5: 0.5
A6: 2 | B6: 4310 | E6: =B5 -> 4200 | F6: =$R$9*B6+(1-$R$9)*H6 -> 4310 | G6: =$R$10*(F6-F5)+(1-$R$10)*G5 -> 110 | H6: =F5+G5 -> 4310 | I6: =INTERCEPT($B$5:$B$28,$A$5:$A$28)+SLOPE($B$5:$B$28,$A$5:$A$28)*A6 -> 4467.5986 | Q6: Peso intermedio | R6: 0.3
A7: 3 | B7: 4475 | E7: =$R$8*B6+(1-$R$8)*E6 -> 4233 | F7: =$R$9*B7+(1-$R$9)*H7 -> 4442 | G7: =$R$10*(F7-F6)+(1-$R$10)*G6 -> 114.4 | H7: =F6+G6 -> 4420 | I7: =INTERCEPT($B$5:$B$28,$A$5:$A$28)+SLOPE($B$5:$B$28,$A$5:$A$28)*A7 -> 4502.0138 | Q7: Peso antiguo | R7: 0.2
A8: 4 | B8: 4590 | C8: =AVERAGE(B5:B7) -> 4328.3333 | D8: =$R$5*B7+$R$6*B6+$R$7*B5 -> 4370.5 | E8: =$R$8*B7+(1-$R$8)*E7 -> 4305.6 | F8: =$R$9*B8+(1-$R$9)*H8 -> 4569.84 | G8: =$R$10*(F8-F7)+(1-$R$10)*G7 -> 117.088 | H8: =F7+G7 -> 4556.4 | I8: =INTERCEPT($B$5:$B$28,$A$5:$A$28)+SLOPE($B$5:$B$28,$A$5:$A$28)*A8 -> 4536.429 | J8: =B8-C8 -> 261.66667 | K8: =ABS(J8) -> 261.66667 | L8: =J8^2 -> 68469.444 | M8: =IF(B8=0,"",K8/B8*100) -> 5.7007988 | Q8: α SES | R8: 0.3
A9: 5 | B9: 4620 | C9: =AVERAGE(B6:B8) -> 4458.3333 | D9: =$R$5*B8+$R$6*B7+$R$7*B6 -> 4499.5 | E9: =$R$8*B8+(1-$R$8)*E8 -> 4390.92 | F9: =$R$9*B9+(1-$R$9)*H9 -> 4660.1568 | G9: =$R$10*(F9-F8)+(1-$R$10)*G8 -> 111.73376 | H9: =F8+G8 -> 4686.928 | I9: =INTERCEPT($B$5:$B$28,$A$5:$A$28)+SLOPE($B$5:$B$28,$A$5:$A$28)*A9 -> 4570.8442 | J9: =B9-C9 -> 161.66667 | K9: =ABS(J9) -> 161.66667 | L9: =J9^2 -> 26136.111 | M9: =IF(B9=0,"",K9/B9*100) -> 3.4992785 | Q9: α Holt | R9: 0.4
A10: 6 | B10: 4780 | C10: =AVERAGE(B7:B9) -> 4561.6667 | D10: =$R$5*B9+$R$6*B8+$R$7*B7 -> 4582 | E10: =$R$8*B9+(1-$R$8)*E9 -> 4459.644 | F10: =$R$9*B10+(1-$R$9)*H10 -> 4775.1343 | G10: =$R$10*(F10-F9)+(1-$R$10)*G9 -> 112.38252 | H10: =F9+G9 -> 4771.8906 | I10: =INTERCEPT($B$5:$B$28,$A$5:$A$28)+SLOPE($B$5:$B$28,$A$5:$A$28)*A10 -> 4605.2594 | J10: =B10-C10 -> 218.33333 | K10: =ABS(J10) -> 218.33333 | L10: =J10^2 -> 47669.444 | M10: =IF(B10=0,"",K10/B10*100) -> 4.567643 | Q10: β Holt | R10: 0.2
A11: 7 | B11: 4850 | C11: =AVERAGE(B8:B10) -> 4663.3333 | D11: =$R$5*B10+$R$6*B9+$R$7*B8 -> 4694 | E11: =$R$8*B10+(1-$R$8)*E10 -> 4555.7508 | F11: =$R$9*B11+(1-$R$9)*H11 -> 4872.5101 | G11: =$R$10*(F11-F10)+(1-$R$10)*G10 -> 109.38117 | H11: =F10+G10 -> 4887.5169 | I11: =INTERCEPT($B$5:$B$28,$A$5:$A$28)+SLOPE($B$5:$B$28,$A$5:$A$28)*A11 -> 4639.6746 | J11: =B11-C11 -> 186.66667 | K11: =ABS(J11) -> 186.66667 | L11: =J11^2 -> 34844.444 | M11: =IF(B11=0,"",K11/B11*100) -> 3.8487973
A12: 8 | B12: 4710 | C12: =AVERAGE(B9:B11) -> 4750 | D12: =$R$5*B11+$R$6*B10+$R$7*B9 -> 4783 | E12: =$R$8*B11+(1-$R$8)*E11 -> 4644.0256 | F12: =$R$9*B12+(1-$R$9)*H12 -> 4873.1348 | G12: =$R$10*(F12-F11)+(1-$R$10)*G11 -> 87.629865 | H12: =F11+G11 -> 4981.8913 | I12: =INTERCEPT($B$5:$B$28,$A$5:$A$28)+SLOPE($B$5:$B$28,$A$5:$A$28)*A12 -> 4674.0899 | J12: =B12-C12 -> -40 | K12: =ABS(J12) -> 40 | L12: =J12^2 -> 1600 | M12: =IF(B12=0,"",K12/B12*100) -> 0.8492569 | Q12: PMS t=4 | R12: =C8 -> 4328.3333
A13: 9 | B13: 4660 | C13: =AVERAGE(B10:B12) -> 4780 | D13: =$R$5*B12+$R$6*B11+$R$7*B10 -> 4766 | E13: =$R$8*B12+(1-$R$8)*E12 -> 4663.8179 | F13: =$R$9*B13+(1-$R$9)*H13 -> 4840.4588 | G13: =$R$10*(F13-F12)+(1-$R$10)*G12 -> 63.568694 | H13: =F12+G12 -> 4960.7646 | I13: =INTERCEPT($B$5:$B$28,$A$5:$A$28)+SLOPE($B$5:$B$28,$A$5:$A$28)*A13 -> 4708.5051 | J13: =B13-C13 -> -120 | K13: =ABS(J13) -> 120 | L13: =J13^2 -> 14400 | M13: =IF(B13=0,"",K13/B13*100) -> 2.5751073 | Q13: PMP t=4 | R13: =D8 -> 4370.5
A14: 10 | B14: 4930 | C14: =AVERAGE(B11:B13) -> 4740 | D14: =$R$5*B13+$R$6*B12+$R$7*B11 -> 4713 | E14: =$R$8*B13+(1-$R$8)*E13 -> 4662.6725 | F14: =$R$9*B14+(1-$R$9)*H14 -> 4914.4165 | G14: =$R$10*(F14-F13)+(1-$R$10)*G13 -> 65.646496 | H14: =F13+G13 -> 4904.0275 | I14: =INTERCEPT($B$5:$B$28,$A$5:$A$28)+SLOPE($B$5:$B$28,$A$5:$A$28)*A14 -> 4742.9203 | J14: =B14-C14 -> 190 | K14: =ABS(J14) -> 190 | L14: =J14^2 -> 36100 | M14: =IF(B14=0,"",K14/B14*100) -> 3.8539554 | Q14: SES t=25 | R14: =E29 -> 5273.1764
A15: 11 | B15: 5280 | C15: =AVERAGE(B12:B14) -> 4766.6667 | D15: =$R$5*B14+$R$6*B13+$R$7*B12 -> 4805 | E15: =$R$8*B14+(1-$R$8)*E14 -> 4742.8708 | F15: =$R$9*B15+(1-$R$9)*H15 -> 5100.0378 | G15: =$R$10*(F15-F14)+(1-$R$10)*G14 -> 89.641458 | H15: =F14+G14 -> 4980.063 | I15: =INTERCEPT($B$5:$B$28,$A$5:$A$28)+SLOPE($B$5:$B$28,$A$5:$A$28)*A15 -> 4777.3355 | J15: =B15-C15 -> 513.33333 | K15: =ABS(J15) -> 513.33333 | L15: =J15^2 -> 263511.11 | M15: =IF(B15=0,"",K15/B15*100) -> 9.7222222 | Q15: Holt t=25 | R15: =F28+G28 -> 5523.4414
A16: 12 | B16: 5560 | C16: =AVERAGE(B13:B15) -> 4956.6667 | D16: =$R$5*B15+$R$6*B14+$R$7*B13 -> 5051 | E16: =$R$8*B15+(1-$R$8)*E15 -> 4904.0095 | F16: =$R$9*B16+(1-$R$9)*H16 -> 5337.8075 | G16: =$R$10*(F16-F15)+(1-$R$10)*G15 -> 119.26712 | H16: =F15+G15 -> 5189.6792 | I16: =INTERCEPT($B$5:$B$28,$A$5:$A$28)+SLOPE($B$5:$B$28,$A$5:$A$28)*A16 -> 4811.7507 | J16: =B16-C16 -> 603.33333 | K16: =ABS(J16) -> 603.33333 | L16: =J16^2 -> 364011.11 | M16: =IF(B16=0,"",K16/B16*100) -> 10.851319 | Q16: Regresión t=25 | R16: =FORECAST(25,B5:B28,A5:A28) -> 5259.1486
A17: 13 | B17: 4340 | C17: =AVERAGE(B14:B16) -> 5256.6667 | D17: =$R$5*B16+$R$6*B15+$R$7*B14 -> 5350 | E17: =$R$8*B16+(1-$R$8)*E16 -> 5100.8067 | F17: =$R$9*B17+(1-$R$9)*H17 -> 5010.2448 | G17: =$R$10*(F17-F16)+(1-$R$10)*G16 -> 29.901145 | H17: =F16+G16 -> 5457.0747 | I17: =INTERCEPT($B$5:$B$28,$A$5:$A$28)+SLOPE($B$5:$B$28,$A$5:$A$28)*A17 -> 4846.1659 | J17: =B17-C17 -> -916.66667 | K17: =ABS(J17) -> 916.66667 | L17: =J17^2 -> 840277.78 | M17: =IF(B17=0,"",K17/B17*100) -> 21.121352 | Q17: PMS t=25 | R17: =AVERAGE(B26:B28) -> 5413.3333
A18: 14 | B18: 4450 | C18: =AVERAGE(B15:B17) -> 5060 | D18: =$R$5*B17+$R$6*B16+$R$7*B15 -> 4894 | E18: =$R$8*B17+(1-$R$8)*E17 -> 4872.5647 | F18: =$R$9*B18+(1-$R$9)*H18 -> 4804.0876 | G18: =$R$10*(F18-F17)+(1-$R$10)*G17 -> -17.310531 | H18: =F17+G17 -> 5040.1459 | I18: =INTERCEPT($B$5:$B$28,$A$5:$A$28)+SLOPE($B$5:$B$28,$A$5:$A$28)*A18 -> 4880.5812 | J18: =B18-C18 -> -610 | K18: =ABS(J18) -> 610 | L18: =J18^2 -> 372100 | M18: =IF(B18=0,"",K18/B18*100) -> 13.707865 | Q18: MAD PMS | R18: =AVERAGE(K8:K28) -> 307.38095
A19: 15 | B19: 4610 | C19: =AVERAGE(B16:B18) -> 4783.3333 | D19: =$R$5*B18+$R$6*B17+$R$7*B16 -> 4639 | E19: =$R$8*B18+(1-$R$8)*E18 -> 4745.7953 | F19: =$R$9*B19+(1-$R$9)*H19 -> 4716.0662 | G19: =$R$10*(F19-F18)+(1-$R$10)*G18 -> -31.452693 | H19: =F18+G18 -> 4786.777 | I19: =INTERCEPT($B$5:$B$28,$A$5:$A$28)+SLOPE($B$5:$B$28,$A$5:$A$28)*A19 -> 4914.9964 | J19: =B19-C19 -> -173.33333 | K19: =ABS(J19) -> 173.33333 | L19: =J19^2 -> 30044.444 | M19: =IF(B19=0,"",K19/B19*100) -> 3.7599422 | Q19: MSE PMS | R19: =AVERAGE(L8:L28) -> 143397.22
A20: 16 | B20: 4740 | C20: =AVERAGE(B17:B19) -> 4466.6667 | D20: =$R$5*B19+$R$6*B18+$R$7*B17 -> 4508 | E20: =$R$8*B19+(1-$R$8)*E19 -> 4705.0567 | F20: =$R$9*B20+(1-$R$9)*H20 -> 4706.7681 | G20: =$R$10*(F20-F19)+(1-$R$10)*G19 -> -27.021776 | H20: =F19+G19 -> 4684.6135 | I20: =INTERCEPT($B$5:$B$28,$A$5:$A$28)+SLOPE($B$5:$B$28,$A$5:$A$28)*A20 -> 4949.4116 | J20: =B20-C20 -> 273.33333 | K20: =ABS(J20) -> 273.33333 | L20: =J20^2 -> 74711.111 | M20: =IF(B20=0,"",K20/B20*100) -> 5.766526 | Q20: MAPE PMS (%) | R20: =AVERAGE(M8:M28) -> 6.2604028
A21: 17 | B21: 4820 | C21: =AVERAGE(B18:B20) -> 4600 | D21: =$R$5*B20+$R$6*B19+$R$7*B18 -> 4643 | E21: =$R$8*B20+(1-$R$8)*E20 -> 4715.5397 | F21: =$R$9*B21+(1-$R$9)*H21 -> 4735.8478 | G21: =$R$10*(F21-F20)+(1-$R$10)*G20 -> -15.801483 | H21: =F20+G20 -> 4679.7463 | I21: =INTERCEPT($B$5:$B$28,$A$5:$A$28)+SLOPE($B$5:$B$28,$A$5:$A$28)*A21 -> 4983.8268 | J21: =B21-C21 -> 220 | K21: =ABS(J21) -> 220 | L21: =J21^2 -> 48400 | M21: =IF(B21=0,"",K21/B21*100) -> 4.5643154 | Q21: Señal de rastreo PMS | R21: =SUM(J8:J28)/R18 -> 7.4446166
A22: 18 | B22: 4970 | C22: =AVERAGE(B19:B21) -> 4723.3333 | D22: =$R$5*B21+$R$6*B20+$R$7*B19 -> 4754 | E22: =$R$8*B21+(1-$R$8)*E21 -> 4746.8778 | F22: =$R$9*B22+(1-$R$9)*H22 -> 4820.0278 | G22: =$R$10*(F22-F21)+(1-$R$10)*G21 -> 4.1948113 | H22: =F21+G21 -> 4720.0463 | I22: =INTERCEPT($B$5:$B$28,$A$5:$A$28)+SLOPE($B$5:$B$28,$A$5:$A$28)*A22 -> 5018.242 | J22: =B22-C22 -> 246.66667 | K22: =ABS(J22) -> 246.66667 | L22: =J22^2 -> 60844.444 | M22: =IF(B22=0,"",K22/B22*100) -> 4.963112
A23: 19 | B23: 5060 | C23: =AVERAGE(B20:B22) -> 4843.3333 | D23: =$R$5*B22+$R$6*B21+$R$7*B20 -> 4879 | E23: =$R$8*B22+(1-$R$8)*E22 -> 4813.8144 | F23: =$R$9*B23+(1-$R$9)*H23 -> 4918.5336 | G23: =$R$10*(F23-F22)+(1-$R$10)*G22 -> 23.057003 | H23: =F22+G22 -> 4824.2226 | I23: =INTERCEPT($B$5:$B$28,$A$5:$A$28)+SLOPE($B$5:$B$28,$A$5:$A$28)*A23 -> 5052.6572 | J23: =B23-C23 -> 216.66667 | K23: =ABS(J23) -> 216.66667 | L23: =J23^2 -> 46944.444 | M23: =IF(B23=0,"",K23/B23*100) -> 4.2819499 | Q23: Convención | R23: SES F₂=D₁; Holt L₁=D₁, T₁=D₂−D₁; APE=|Real−Pronóstico|/Real×100. Validar con Producción.
A24: 20 | B24: 4890 | C24: =AVERAGE(B21:B23) -> 4950 | D24: =$R$5*B23+$R$6*B22+$R$7*B21 -> 4985 | E24: =$R$8*B23+(1-$R$8)*E23 -> 4887.6701 | F24: =$R$9*B24+(1-$R$9)*H24 -> 4920.9543 | G24: =$R$10*(F24-F23)+(1-$R$10)*G23 -> 18.929758 | H24: =F23+G23 -> 4941.5906 | I24: =INTERCEPT($B$5:$B$28,$A$5:$A$28)+SLOPE($B$5:$B$28,$A$5:$A$28)*A24 -> 5087.0725 | J24: =B24-C24 -> -60 | K24: =ABS(J24) -> 60 | L24: =J24^2 -> 3600 | M24: =IF(B24=0,"",K24/B24*100) -> 1.2269939 | Q24: Tolerancia | R24: Provisional: 0,01 % relativo en valores; 0,01 puntos en MAPE. Pendiente de firma.
A25: 21 | B25: 4810 | C25: =AVERAGE(B22:B24) -> 4973.3333 | D25: =$R$5*B24+$R$6*B23+$R$7*B22 -> 4957 | E25: =$R$8*B24+(1-$R$8)*E24 -> 4888.3691 | F25: =$R$9*B25+(1-$R$9)*H25 -> 4887.9305 | G25: =$R$10*(F25-F24)+(1-$R$10)*G24 -> 8.5390299 | H25: =F24+G24 -> 4939.8841 | I25: =INTERCEPT($B$5:$B$28,$A$5:$A$28)+SLOPE($B$5:$B$28,$A$5:$A$28)*A25 -> 5121.4877 | J25: =B25-C25 -> -163.33333 | K25: =ABS(J25) -> 163.33333 | L25: =J25^2 -> 26677.778 | M25: =IF(B25=0,"",K25/B25*100) -> 3.3957034
A26: 22 | B26: 5090 | C26: =AVERAGE(B23:B25) -> 4920 | D26: =$R$5*B25+$R$6*B24+$R$7*B23 -> 4884 | E26: =$R$8*B25+(1-$R$8)*E25 -> 4864.8584 | F26: =$R$9*B26+(1-$R$9)*H26 -> 4973.8817 | G26: =$R$10*(F26-F25)+(1-$R$10)*G25 -> 24.021471 | H26: =F25+G25 -> 4896.4695 | I26: =INTERCEPT($B$5:$B$28,$A$5:$A$28)+SLOPE($B$5:$B$28,$A$5:$A$28)*A26 -> 5155.9029 | J26: =B26-C26 -> 170 | K26: =ABS(J26) -> 170 | L26: =J26^2 -> 28900 | M26: =IF(B26=0,"",K26/B26*100) -> 3.3398821
A27: 23 | B27: 5430 | C27: =AVERAGE(B24:B26) -> 4930 | D27: =$R$5*B26+$R$6*B25+$R$7*B24 -> 4966 | E27: =$R$8*B26+(1-$R$8)*E26 -> 4932.4008 | F27: =$R$9*B27+(1-$R$9)*H27 -> 5170.7419 | G27: =$R$10*(F27-F26)+(1-$R$10)*G26 -> 58.589218 | H27: =F26+G26 -> 4997.9032 | I27: =INTERCEPT($B$5:$B$28,$A$5:$A$28)+SLOPE($B$5:$B$28,$A$5:$A$28)*A27 -> 5190.3181 | J27: =B27-C27 -> 500 | K27: =ABS(J27) -> 500 | L27: =J27^2 -> 250000 | M27: =IF(B27=0,"",K27/B27*100) -> 9.2081031
A28: 24 | B28: 5720 | C28: =AVERAGE(B25:B27) -> 5110 | D28: =$R$5*B27+$R$6*B26+$R$7*B25 -> 5204 | E28: =$R$8*B27+(1-$R$8)*E27 -> 5081.6806 | F28: =$R$9*B28+(1-$R$9)*H28 -> 5425.5987 | G28: =$R$10*(F28-F27)+(1-$R$10)*G27 -> 97.842728 | H28: =F27+G27 -> 5229.3311 | I28: =INTERCEPT($B$5:$B$28,$A$5:$A$28)+SLOPE($B$5:$B$28,$A$5:$A$28)*A28 -> 5224.7333 | J28: =B28-C28 -> 610 | K28: =ABS(J28) -> 610 | L28: =J28^2 -> 372100 | M28: =IF(B28=0,"",K28/B28*100) -> 10.664336
E29: =$R$8*B28+(1-$R$8)*E28 -> 5273.1764

Sheet Catalogo
A1: Catálogo de casos de prueba (Anexo A del plan maestro)
A2: Camilo: casos basados en el backlog oficial y el prototipo Pronostica. Requisitos y Matriz requieren actualización del equipo.
A4: ID caso | B4: ID requisito | C4: Módulo (auto) | D4: Nivel | E4: Técnica | F4: Prioridad | G4: Precondiciones | H4: Datos de entrada | I4: Pasos | J4: Resultado esperado | K4: Tolerancia | L4: Resultado obtenido | M4: Veredicto | N4: Defecto asociado | O4: Ejecutor | P4: Fecha
A5: CP-001 | B5: RF-11 | C5: pronostico | D5: Unitaria | E5: Verificación numérica | F5: Alta | G5: Serie sintética CAF-500 de 24 meses | H5: PMS n=3; t=4 | I5: Ejecutar y consultar t=4 | J5: PMS t=4 = Calculo_Referencia!R12 | K5: 0,01 % | M5: =Verificacion!H5 -> PENDIENTE
A6: CP-002 | B6: RF-12 | C6: pronostico | D6: Unitaria | E6: Verificación numérica | F6: Alta | G6: Misma serie | H6: PMP pesos 0,5/0,3/0,2; t=4 | I6: Ejecutar y consultar t=4 | J6: PMP t=4 = Calculo_Referencia!R13 | K6: 0,01 % | M6: =Verificacion!H6 -> PENDIENTE
A7: CP-003 | B7: RF-13 | C7: pronostico | D7: Unitaria | E7: Verificación numérica | F7: Alta | G7: Misma serie | H7: SES α=0,3; F₂=D₁ | I7: Ejecutar a horizonte 1 | J7: SES t=25 = Calculo_Referencia!R14 | K7: 0,01 % | M7: =Verificacion!H7 -> PENDIENTE
A8: CP-004 | B8: RF-14 | C8: pronostico | D8: Unitaria | E8: Verificación numérica | F8: Alta | G8: Misma serie | H8: Holt α=0,4; β=0,2 | I8: Ejecutar a horizonte 1 | J8: Holt t=25 = Calculo_Referencia!R15 | K8: 0,01 % | M8: =Verificacion!H8 -> PENDIENTE
A9: CP-005 | B9: RF-15 | C9: pronostico | D9: Unitaria | E9: Verificación numérica | F9: Alta | G9: Misma serie | H9: Regresión lineal | I9: Ejecutar a horizonte 1 | J9: Regresión t=25 = Calculo_Referencia!R16 | K9: 0,01 % | M9: =Verificacion!H9 -> PENDIENTE
A10: CP-006 | B10: RF-11 | C10: pronostico | D10: Unitaria | E10: Verificación numérica | F10: Alta | G10: Misma serie | H10: PMS n=3; t=25 | I10: Ejecutar a horizonte 1 | J10: PMS t=25 = Calculo_Referencia!R17 | K10: 0,01 % | M10: =Verificacion!H10 -> PENDIENTE
A11: CP-007 | B11: RF-17 | C11: pronostico | D11: Unitaria | E11: Verificación numérica | F11: Alta | G11: Misma serie | H11: PMS n=3; t=4–24 | I11: Consultar MAD | J11: MAD = Calculo_Referencia!R18 | K11: 0,01 % | M11: =Verificacion!H11 -> PENDIENTE
A12: CP-008 | B12: RF-17 | C12: pronostico | D12: Unitaria | E12: Verificación numérica | F12: Alta | G12: Misma serie | H12: PMS n=3; t=4–24 | I12: Consultar MSE | J12: MSE = Calculo_Referencia!R19 | K12: 0,01 % | M12: =Verificacion!H12 -> PENDIENTE
A13: CP-009 | B13: RF-17 | C13: pronostico | D13: Unitaria | E13: Verificación numérica | F13: Alta | G13: Misma serie | H13: PMS n=3; t=4–24 | I13: Consultar MAPE | J13: MAPE = Calculo_Referencia!R20 | K13: 0,01 puntos | M13: =Verificacion!H13 -> PENDIENTE
A14: CP-010 | B14: RF-17 | C14: pronostico | D14: Unitaria | E14: Verificación numérica | F14: Alta | G14: Misma serie | H14: PMS n=3; t=4–24 | I14: Consultar señal de rastreo | J14: Señal = Calculo_Referencia!R21 | K14: 0,01 % | M14: =Verificacion!H14 -> PENDIENTE
A15: CP-011 | B15: RF-01 | C15: auth | D15: Sistema/Funcional | E15: Partición de equivalencia | F15: Alta | G15: Usuario activo | H15: Credenciales válidas e inválidas | I15: Iniciar/cerrar sesión; esperar inactividad | J15: Solo credenciales válidas acceden; sesión expira | M15: PENDIENTE
A16: CP-012 | B16: RF-02 | C16: auth | D16: Sistema/Funcional | E16: Tabla de decisión | F16: Alta | G16: Administrador autenticado | H16: Crear, editar, desactivar y asignar rol | I16: Ejecutar cada acción | J16: Cambios persistidos; cuatro roles disponibles | M16: PENDIENTE
A17: CP-013 | B17: RF-03 | C17: auth | D17: Seguridad | E17: Tabla de decisión | F17: Alta | G17: Sesiones de los cuatro roles | H17: Ruta y API sin permiso | I17: Abrir opción y llamar API | J17: Opción oculta y respuesta 403 | M17: PENDIENTE
A18: CP-014 | B18: RF-04 | C18: datos | D18: Sistema/Funcional | E18: Partición de equivalencia | F18: Alta | G18: Administrador o analista | H18: Tres productos de prueba | I18: Crear, consultar, editar y dar de baja | J18: Código, nombre, categoría y unidad conservados | M18: PENDIENTE
A19: CP-015 | B19: RF-05 | C19: datos | D19: Integración | E19: Valores límite | F19: Alta | G19: Analista autenticado | H19: Mismo producto y mes dos veces | I19: Registrar duplicado | J19: Segundo registro rechazado | M19: PENDIENTE
A20: CP-016 | B20: RF-06 | C20: datos | D20: Integración | E20: Partición de equivalencia | F20: Alta | G20: Analista autenticado | H20: CSV/XLSX con 24 filas y una inválida | I20: Importar archivo | J20: Informa filas cargadas/rechazadas y motivo | M20: PENDIENTE
A21: CP-017 | B21: RF-07 | C21: datos | D21: Integración | E21: Valores límite | F21: Media | G21: Histórico cargado | H21: Un faltante y un atípico | I21: Detectar y corregir/imputar | J21: Marca ambos y conserva valor original | M21: PENDIENTE
A22: CP-018 | B22: RF-08 | C22: datos | D22: Sistema/Funcional | E22: Partición de equivalencia | F22: Media | G22: Supervisor autenticado | H22: Centro, mes y capacidad | I22: Registrar capacidad | J22: Capacidad asociada al centro y mes | M22: PENDIENTE
A23: CP-019 | B23: RF-09 | C23: datos | D23: Sistema/Funcional | E23: Partición de equivalencia | F23: Alta | G23: 24 períodos por producto | H23: CAF-500 y rango completo | I23: Abrir tabla y gráfico | J23: Muestra 24 puntos del producto correcto | M23: PENDIENTE
A24: CP-020 | B24: RF-10 | C24: pronostico | D24: Unitaria | E24: Valores límite | F24: Alta | G24: Planeador autenticado | H24: α=-0,1; β=1,1; pesos suman 0,9 | I24: Guardar parámetros | J24: Rechaza cada valor inválido | M24: PENDIENTE
A25: CP-021 | B25: RF-16 | C25: pronostico | D25: Unitaria | E25: Basada en riesgo | F25: Alta | G25: Serie sintética CAF-500 de 24 meses | H25: Método estacional multiplicativo | I25: Ejecutar y revisar índices | J25: Presenta 12 índices; cálculo externo por validar | K25: Pendiente | M25: PENDIENTE
A26: CP-022 | B26: RF-18 | C26: pronostico | D26: Sistema/Funcional | E26: Basada en riesgo | F26: Alta | G26: Serie cargada | H26: Ejecutar seis métodos | I26: Abrir comparación | J26: Seis modelos ordenados por MAPE; menor señalado | M26: PENDIENTE
A27: CP-023 | B27: RF-19 | C27: pronostico | D27: Integración | E27: Transición de estados | F27: Media | G27: Planeador autenticado | H27: Ejecución con parámetros | I27: Guardar y reabrir historial | J27: Conserva usuario, fecha, parámetros y resultados | M27: PENDIENTE
A28: CP-024 | B28: RF-20 | C28: indicadores-reportes | D28: Sistema/Funcional | E28: Basada en riesgo | F28: Alta | G28: Modelo ejecutado | H28: CAF-500 y PMS | I28: Abrir tablero | J28: MAD/MAPE coinciden con ejecución vigente | M28: PENDIENTE
A29: CP-025 | B29: RF-21 | C29: indicadores-reportes | D29: Sistema/Funcional | E29: Basada en riesgo | F29: Alta | G29: Modelo ejecutado | H29: CAF-500, 24 meses | I29: Abrir gráfico | J29: Real y pronóstico superpuestos; sesgo correcto | M29: PENDIENTE
A30: CP-026 | B30: RF-22 | C30: indicadores-reportes | D30: Sistema/Funcional | E30: Valores límite | F30: Media | G30: Capacidad registrada | H30: Plan mayor y menor que capacidad | I30: Abrir plan por centro | J30: Resalta sobrecarga y subutilización | M30: PENDIENTE
A31: CP-027 | B31: RF-23 | C31: indicadores-reportes | D31: Unitaria | E31: Valores límite | F31: Media | G31: Planeador autenticado | H31: MAPE sobre umbral; señal fuera de límites | I31: Evaluar alertas | J31: Se muestra alerta correspondiente | M31: PENDIENTE
A32: CP-028 | B32: RF-24 | C32: indicadores-reportes | D32: Sistema/Funcional | E32: Partición de equivalencia | F32: Media | G32: Tablero con datos | H32: Filtros y PDF/XLSX | I32: Exportar ambos formatos | J32: Filas y valores coinciden con pantalla | M32: PENDIENTE
A33: CP-029 | B33: RF-25 | C33: auth | D33: Integración | E33: Transición de estados | F33: Media | G33: Administrador autenticado | H33: Carga, ejecución y cambio de rol | I33: Consultar auditoría | J33: Registros con usuario y fecha | M33: PENDIENTE
A34: CP-030 | B34: RNF-01 | C34: pronostico | D34: Rendimiento | E34: Basada en riesgo | F34: Alta | G34: 24 meses × 3 productos | H34: Seis métodos por producto | I34: Medir tiempo | J34: ≤3 s un producto; ≤10 s tres productos | M34: PENDIENTE
A35: CP-031 | B35: RNF-05 | C35: auth | D35: Seguridad | E35: Tabla de decisión | F35: Alta | G35: Sin JWT y luego rol sin permiso | H35: Rutas protegidas | I35: Solicitar API | J35: 401 sin JWT; 403 sin permiso | M35: PENDIENTE
A36: CP-032 | B36: RNF-08 | C36: pronostico | D36: Unitaria | E36: Basada en riesgo | F36: Alta | G36: Serie sintética CAF-500 de 24 meses | H36: CP-001 a CP-010 | I36: Comparar con referencia | J36: Diferencia dentro de tolerancia acordada | K36: 0,01 % provisional | M36: PENDIENTE
A37: CP-033 | B37: RNF-09 | C37: datos | D37: Integración | E37: Transición de estados | F37: Alta | G37: Histórico cargado | H37: Corregir valor | I37: Consultar auditoría y dato | J37: Nuevo valor y original trazables | M37: PENDIENTE
A38: CP-034 | B38: RNF-10 | C38: Frontend | D38: Aceptación | E38: Exploratoria | F38: Media | G38: Usuarios de Producción | H38: Tareas principales | I38: Observar sin ayuda | J38: ≥80 % de tareas completadas sin ayuda | M38: PENDIENTE
A39: CP-035 | B39: RNF-11 | C39: Frontend | D39: Sistema/Funcional | E39: Valores límite | F39: Media | G39: Navegador abierto | H39: Escritorio y tableta | I39: Navegar pantallas | J39: Funciones disponibles sin pérdida | M39: PENDIENTE
A40: CP-036 | B40: RNF-02 | C40: {=IF(B40="","",IFERROR(INDEX(Requisitos!$C$5:$C$60,MATCH(B40,Requisitos!$A$5:$A$60,0)),"¿Requisito no existe?"))} -> Indicadores y reportes | D40: Sistema/Funcional | E40: Rendimiento | F40: Media | G40: Base de datos con histórico de 24 meses cargado | H40: Consulta inicial del tablero principal | I40: Navegar al módulo de Indicadores y medir tiempo de respuesta con DevTools | J40: Tiempo de carga inicial e interactividad total <= 2 s | K40: N/A | M40: PENDIENTE
A41: CP-037 | B41: RNF-03 | C41: {=IF(B41="","",IFERROR(INDEX(Requisitos!$C$5:$C$60,MATCH(B41,Requisitos!$A$5:$A$60,0)),"¿Requisito no existe?"))} -> Transversal | D41: Sistema/Funcional | E41: Basada en riesgo | F41: Media | G41: Dataset de prueba masivo preparado | H41: 50 productos con 60 períodos de demanda cada uno | I41: Importar dataset masivo y ejecutar cálculo global de modelos | J41: Sistema procesa y almacena los datos sin errores ni modificaciones de código | K41: N/A | M41: PENDIENTE
...

Sheet Verificacion
A1: Verificación numérica: sistema vs. cálculo de referencia
A2: Referencia enlazada a Calculo_Referencia; valor del sistema (D) se llena solo tras ejecutar con los mismos 24 datos. Tolerancia provisional pendiente de Producción.
A4: ID caso | B4: Qué se verifica | C4: Valor de referencia (Excel) | D4: Valor del sistema | E4: Diferencia absoluta | F4: Tolerancia | G4: Unidad | H4: Veredicto | I4: Defecto asociado
A5: CP-001 | B5: PMS t=4 | C5: =Calculo_Referencia!R12 -> 4328.3333 | E5: =IF(OR(C5="",D5=""),"",ABS(D5-C5)) | F5: 0.01 | G5: % relativo | H5: =IF(C5="","",IF(D5="","PENDIENTE",IF(IF(C5=0,E5,E5/ABS(C5)*100)<=F5,"APROBADO","FALLIDO"))) -> PENDIENTE
A6: CP-002 | B6: PMP t=4 | C6: =Calculo_Referencia!R13 -> 4370.5 | E6: =IF(OR(C6="",D6=""),"",ABS(D6-C6)) | F6: 0.01 | G6: % relativo | H6: =IF(C6="","",IF(D6="","PENDIENTE",IF(IF(C6=0,E6,E6/ABS(C6)*100)<=F6,"APROBADO","FALLIDO"))) -> PENDIENTE
A7: CP-003 | B7: SES t=25 | C7: =Calculo_Referencia!R14 -> 5273.1764 | E7: =IF(OR(C7="",D7=""),"",ABS(D7-C7)) | F7: 0.01 | G7: % relativo | H7: =IF(C7="","",IF(D7="","PENDIENTE",IF(IF(C7=0,E7,E7/ABS(C7)*100)<=F7,"APROBADO","FALLIDO"))) -> PENDIENTE
A8: CP-004 | B8: Holt t=25 | C8: =Calculo_Referencia!R15 -> 5523.4414 | E8: =IF(OR(C8="",D8=""),"",ABS(D8-C8)) | F8: 0.01 | G8: % relativo | H8: =IF(C8="","",IF(D8="","PENDIENTE",IF(IF(C8=0,E8,E8/ABS(C8)*100)<=F8,"APROBADO","FALLIDO"))) -> PENDIENTE
A9: CP-005 | B9: Regresión t=25 | C9: =Calculo_Referencia!R16 -> 5259.1486 | E9: =IF(OR(C9="",D9=""),"",ABS(D9-C9)) | F9: 0.01 | G9: % relativo | H9: =IF(C9="","",IF(D9="","PENDIENTE",IF(IF(C9=0,E9,E9/ABS(C9)*100)<=F9,"APROBADO","FALLIDO"))) -> PENDIENTE
A10: CP-006 | B10: PMS t=25 | C10: =Calculo_Referencia!R17 -> 5413.3333 | E10: =IF(OR(C10="",D10=""),"",ABS(D10-C10)) | F10: 0.01 | G10: % relativo | H10: =IF(C10="","",IF(D10="","PENDIENTE",IF(IF(C10=0,E10,E10/ABS(C10)*100)<=F10,"APROBADO","FALLIDO"))) -> PENDIENTE
A11: CP-007 | B11: MAD PMS | C11: =Calculo_Referencia!R18 -> 307.38095 | E11: =IF(OR(C11="",D11=""),"",ABS(D11-C11)) | F11: 0.01 | G11: % relativo | H11: =IF(C11="","",IF(D11="","PENDIENTE",IF(IF(C11=0,E11,E11/ABS(C11)*100)<=F11,"APROBADO","FALLIDO"))) -> PENDIENTE
A12: CP-008 | B12: MSE PMS | C12: =Calculo_Referencia!R19 -> 143397.22 | E12: =IF(OR(C12="",D12=""),"",ABS(D12-C12)) | F12: 0.01 | G12: % relativo | H12: =IF(C12="","",IF(D12="","PENDIENTE",IF(IF(C12=0,E12,E12/ABS(C12)*100)<=F12,"APROBADO","FALLIDO"))) -> PENDIENTE
A13: CP-009 | B13: MAPE PMS (%) | C13: =Calculo_Referencia!R20 -> 6.2604028 | E13: =IF(OR(C13="",D13=""),"",ABS(D13-C13)) | F13: 0.01 | G13: puntos | H13: =IF(C13="","",IF(D13="","PENDIENTE",IF(E13<=F13,"APROBADO","FALLIDO"))) -> PENDIENTE
A14: CP-010 | B14: Señal de rastreo PMS | C14: =Calculo_Referencia!R21 -> 7.4446166 | E14: =IF(OR(C14="",D14=""),"",ABS(D14-C14)) | F14: 0.01 | G14: % relativo | H14: =IF(C14="","",IF(D14="","PENDIENTE",IF(IF(C14=0,E14,E14/ABS(C14)*100)<=F14,"APROBADO","FALLIDO"))) -> PENDIENTE
E15: =IF(OR(C15="",D15=""),"",ABS(D15-C15)) | H15: =IF(C15="","",IF(D15="","PENDIENTE",IF(ABS(D15-C15)<=F15,"APROBADO","FALLIDO")))
E16: =IF(OR(C16="",D16=""),"",ABS(D16-C16)) | H16: =IF(C16="","",IF(D16="","PENDIENTE",IF(ABS(D16-C16)<=F16,"APROBADO","FALLIDO")))
E17: =IF(OR(C17="",D17=""),"",ABS(D17-C17)) | H17: =IF(C17="","",IF(D17="","PENDIENTE",IF(ABS(D17-C17)<=F17,"APROBADO","FALLIDO")))
E18: =IF(OR(C18="",D18=""),"",ABS(D18-C18)) | H18: =IF(C18="","",IF(D18="","PENDIENTE",IF(ABS(D18-C18)<=F18,"APROBADO","FALLIDO")))
E19: =IF(OR(C19="",D19=""),"",ABS(D19-C19)) | H19: =IF(C19="","",IF(D19="","PENDIENTE",IF(ABS(D19-C19)<=F19,"APROBADO","FALLIDO")))
E20: =IF(OR(C20="",D20=""),"",ABS(D20-C20)) | H20: =IF(C20="","",IF(D20="","PENDIENTE",IF(ABS(D20-C20)<=F20,"APROBADO","FALLIDO")))
E21: =IF(OR(C21="",D21=""),"",ABS(D21-C21)) | H21: =IF(C21="","",IF(D21="","PENDIENTE",IF(ABS(D21-C21)<=F21,"APROBADO","FALLIDO")))
E22: =IF(OR(C22="",D22=""),"",ABS(D22-C22)) | H22: =IF(C22="","",IF(D22="","PENDIENTE",IF(ABS(D22-C22)<=F22,"APROBADO","FALLIDO")))
E23: =IF(OR(C23="",D23=""),"",ABS(D23-C23)) | H23: =IF(C23="","",IF(D23="","PENDIENTE",IF(ABS(D23-C23)<=F23,"APROBADO","FALLIDO")))
E24: =IF(OR(C24="",D24=""),"",ABS(D24-C24)) | H24: =IF(C24="","",IF(D24="","PENDIENTE",IF(ABS(D24-C24)<=F24,"APROBADO","FALLIDO")))
A26: Escribe en la columna D (amarilla) el valor que devuelve el sistema; el veredicto se calcula solo.
A27: Tolerancia 0,01 = diferencia máxima aceptada, acordada con Producción y firmada en el plan maestro. Los valores del sistema están redondeados a 2 decimales.

Sheet Matriz
A1: Matriz de trazabilidad requisitos–pruebas (E1.2)
A2: Se alimenta sola desde Requisitos y Catalogo. Tú completas: Casos de prueba (lista), Nivel/herramienta y Defectos. El estado y la cobertura se calculan.
A4: ID requisito | B4: Descripción | C4: Módulo | D4: Tipo | E4: Prioridad | F4: Casos de prueba (lista) | G4: N.º casos (auto) | H4: Cobertura (auto) | I4: Nivel / herramienta | J4: Estado (auto) | K4: Defectos asociados
A5: =IF(Requisitos!A5="","",Requisitos!A5) -> RF-01 | B5: =IF($A5="","",Requisitos!B5) -> Iniciar y cerrar sesión con credenciales; la sesión expira por inactividad | C5: =IF($A5="","",Requisitos!C5) -> Autenticación y roles | D5: =IF($A5="","",Requisitos!D5) -> Funcional | E5: =IF($A5="","",Requisitos!E5) -> Alta | G5: =IF($A5="","",COUNTIF(Catalogo!$B$5:$B$104,$A5)) -> 1 | H5: =IF($A5="","",IF(G5=0,"SIN COBERTURA","Cubierto")) -> Cubierto | J5: =IF($A5="","",IF(G5=0,"Sin casos",IF(COUNTIFS(Catalogo!$B$5:$B$104,$A5,Catalogo!$M$5:$M$104,"FALLIDO")>0,"Fallido",IF(COUNTIFS(Catalogo!$B$5:$B$104,$A5,Catalogo!$M$5:$M$104,"APROBADO")=G5,"Aprobado","Pendiente")))) -> Pendiente
A6: =IF(Requisitos!A6="","",Requisitos!A6) -> RF-02 | B6: =IF($A6="","",Requisitos!B6) -> Gestionar usuarios: crear, editar, desactivar y asignar uno de los cuatro roles | C6: =IF($A6="","",Requisitos!C6) -> Autenticación y roles | D6: =IF($A6="","",Requisitos!D6) -> Funcional | E6: =IF($A6="","",Requisitos!E6) -> Alta | G6: =IF($A6="","",COUNTIF(Catalogo!$B$5:$B$104,$A6)) -> 1 | H6: =IF($A6="","",IF(G6=0,"SIN COBERTURA","Cubierto")) -> Cubierto | J6: =IF($A6="","",IF(G6=0,"Sin casos",IF(COUNTIFS(Catalogo!$B$5:$B$104,$A6,Catalogo!$M$5:$M$104,"FALLIDO")>0,"Fallido",IF(COUNTIFS(Catalogo!$B$5:$B$104,$A6,Catalogo!$M$5:$M$104,"APROBADO")=G6,"Aprobado","Pendiente")))) -> Pendiente
A7: =IF(Requisitos!A7="","",Requisitos!A7) -> RF-03 | B7: =IF($A7="","",Requisitos!B7) -> Controlar el acceso por rol a pantallas y endpoints (403 sin permiso) | C7: =IF($A7="","",Requisitos!C7) -> Autenticación y roles | D7: =IF($A7="","",Requisitos!D7) -> Funcional | E7: =IF($A7="","",Requisitos!E7) -> Alta | G7: =IF($A7="","",COUNTIF(Catalogo!$B$5:$B$104,$A7)) -> 1 | H7: =IF($A7="","",IF(G7=0,"SIN COBERTURA","Cubierto")) -> Cubierto | J7: =IF($A7="","",IF(G7=0,"Sin casos",IF(COUNTIFS(Catalogo!$B$5:$B$104,$A7,Catalogo!$M$5:$M$104,"FALLIDO")>0,"Fallido",IF(COUNTIFS(Catalogo!$B$5:$B$104,$A7,Catalogo!$M$5:$M$104,"APROBADO")=G7,"Aprobado","Pendiente")))) -> Pendiente
A8: =IF(Requisitos!A8="","",Requisitos!A8) -> RF-04 | B8: =IF($A8="","",Requisitos!B8) -> CRUD de los 3 productos con código, nombre, categoría y unidad | C8: =IF($A8="","",Requisitos!C8) -> Gestión de datos | D8: =IF($A8="","",Requisitos!D8) -> Funcional | E8: =IF($A8="","",Requisitos!E8) -> Alta | G8: =IF($A8="","",COUNTIF(Catalogo!$B$5:$B$104,$A8)) -> 1 | H8: =IF($A8="","",IF(G8=0,"SIN COBERTURA","Cubierto")) -> Cubierto | J8: =IF($A8="","",IF(G8=0,"Sin casos",IF(COUNTIFS(Catalogo!$B$5:$B$104,$A8,Catalogo!$M$5:$M$104,"FALLIDO")>0,"Fallido",IF(COUNTIFS(Catalogo!$B$5:$B$104,$A8,Catalogo!$M$5:$M$104,"APROBADO")=G8,"Aprobado","Pendiente")))) -> Pendiente
A9: =IF(Requisitos!A9="","",Requisitos!A9) -> RF-05 | B9: =IF($A9="","",Requisitos!B9) -> Registrar manualmente producción y demanda por producto y mes, sin duplicar producto-período | C9: =IF($A9="","",Requisitos!C9) -> Gestión de datos | D9: =IF($A9="","",Requisitos!D9) -> Funcional | E9: =IF($A9="","",Requisitos!E9) -> Alta | G9: =IF($A9="","",COUNTIF(Catalogo!$B$5:$B$104,$A9)) -> 1 | H9: =IF($A9="","",IF(G9=0,"SIN COBERTURA","Cubierto")) -> Cubierto | J9: =IF($A9="","",IF(G9=0,"Sin casos",IF(COUNTIFS(Catalogo!$B$5:$B$104,$A9,Catalogo!$M$5:$M$104,"FALLIDO")>0,"Fallido",IF(COUNTIFS(Catalogo!$B$5:$B$104,$A9,Catalogo!$M$5:$M$104,"APROBADO")=G9,"Aprobado","Pendiente")))) -> Pendiente
A10: =IF(Requisitos!A10="","",Requisitos!A10) -> RF-06 | B10: =IF($A10="","",Requisitos!B10) -> Cargar el histórico desde CSV o Excel (24 períodos) informando filas cargadas y rechazadas | C10: =IF($A10="","",Requisitos!C10) -> Gestión de datos | D10: =IF($A10="","",Requisitos!D10) -> Funcional | E10: =IF($A10="","",Requisitos!E10) -> Alta | G10: =IF($A10="","",COUNTIF(Catalogo!$B$5:$B$104,$A10)) -> 1 | H10: =IF($A10="","",IF(G10=0,"SIN COBERTURA","Cubierto")) -> Cubierto | J10: =IF($A10="","",IF(G10=0,"Sin casos",IF(COUNTIFS(Catalogo!$B$5:$B$104,$A10,Catalogo!$M$5:$M$104,"FALLIDO")>0,"Fallido",IF(COUNTIFS(Catalogo!$B$5:$B$104,$A10,Catalogo!$M$5:$M$104,"APROBADO")=G10,"Aprobado","Pendiente")))) -> Pendiente
A11: =IF(Requisitos!A11="","",Requisitos!A11) -> RF-07 | B11: =IF($A11="","",Requisitos!B11) -> Detectar atípicos y faltantes y permitir corregirlos o imputarlos conservando el original | C11: =IF($A11="","",Requisitos!C11) -> Gestión de datos | D11: =IF($A11="","",Requisitos!D11) -> Funcional | E11: =IF($A11="","",Requisitos!E11) -> Media | G11: =IF($A11="","",COUNTIF(Catalogo!$B$5:$B$104,$A11)) -> 1 | H11: =IF($A11="","",IF(G11=0,"SIN COBERTURA","Cubierto")) -> Cubierto | J11: =IF($A11="","",IF(G11=0,"Sin casos",IF(COUNTIFS(Catalogo!$B$5:$B$104,$A11,Catalogo!$M$5:$M$104,"FALLIDO")>0,"Fallido",IF(COUNTIFS(Catalogo!$B$5:$B$104,$A11,Catalogo!$M$5:$M$104,"APROBADO")=G11,"Aprobado","Pendiente")))) -> Pendiente
A12: =IF(Requisitos!A12="","",Requisitos!A12) -> RF-08 | B12: =IF($A12="","",Requisitos!B12) -> Registrar la capacidad disponible por centro de trabajo y período | C12: =IF($A12="","",Requisitos!C12) -> Gestión de datos | D12: =IF($A12="","",Requisitos!D12) -> Funcional | E12: =IF($A12="","",Requisitos!E12) -> Media | G12: =IF($A12="","",COUNTIF(Catalogo!$B$5:$B$104,$A12)) -> 1 | H12: =IF($A12="","",IF(G12=0,"SIN COBERTURA","Cubierto")) -> Cubierto | J12: =IF($A12="","",IF(G12=0,"Sin casos",IF(COUNTIFS(Catalogo!$B$5:$B$104,$A12,Catalogo!$M$5:$M$104,"FALLIDO")>0,"Fallido",IF(COUNTIFS(Catalogo!$B$5:$B$104,$A12,Catalogo!$M$5:$M$104,"APROBADO")=G12,"Aprobado","Pendiente")))) -> Pendiente
A13: =IF(Requisitos!A13="","",Requisitos!A13) -> RF-09 | B13: =IF($A13="","",Requisitos!B13) -> Visualizar el histórico en tabla y gráfico de líneas con filtros por producto y rango | C13: =IF($A13="","",Requisitos!C13) -> Gestión de datos | D13: =IF($A13="","",Requisitos!D13) -> Funcional | E13: =IF($A13="","",Requisitos!E13) -> Alta | G13: =IF($A13="","",COUNTIF(Catalogo!$B$5:$B$104,$A13)) -> 1 | H13: =IF($A13="","",IF(G13=0,"SIN COBERTURA","Cubierto")) -> Cubierto | J13: =IF($A13="","",IF(G13=0,"Sin casos",IF(COUNTIFS(Catalogo!$B$5:$B$104,$A13,Catalogo!$M$5:$M$104,"FALLIDO")>0,"Fallido",IF(COUNTIFS(Catalogo!$B$5:$B$104,$A13,Catalogo!$M$5:$M$104,"APROBADO")=G13,"Aprobado","Pendiente")))) -> Pendiente
A14: =IF(Requisitos!A14="","",Requisitos!A14) -> RF-10 | B14: =IF($A14="","",Requisitos!B14) -> Configurar parámetros por modelo (n, pesos, α, β, horizonte) validando rangos | C14: =IF($A14="","",Requisitos!C14) -> Pronóstico | D14: =IF($A14="","",Requisitos!D14) -> Funcional | E14: =IF($A14="","",Requisitos!E14) -> Alta | G14: =IF($A14="","",COUNTIF(Catalogo!$B$5:$B$104,$A14)) -> 1 | H14: =IF($A14="","",IF(G14=0,"SIN COBERTURA","Cubierto")) -> Cubierto | J14: =IF($A14="","",IF(G14=0,"Sin casos",IF(COUNTIFS(Catalogo!$B$5:$B$104,$A14,Catalogo!$M$5:$M$104,"FALLIDO")>0,"Fallido",IF(COUNTIFS(Catalogo!$B$5:$B$104,$A14,Catalogo!$M$5:$M$104,"APROBADO")=G14,"Aprobado","Pendiente")))) -> Pendiente
A15: =IF(Requisitos!A15="","",Requisitos!A15) -> RF-11 | B15: =IF($A15="","",Requisitos!B15) -> Ejecutar promedio móvil simple | C15: =IF($A15="","",Requisitos!C15) -> Pronóstico | D15: =IF($A15="","",Requisitos!D15) -> Funcional | E15: =IF($A15="","",Requisitos!E15) -> Alta | G15: =IF($A15="","",COUNTIF(Catalogo!$B$5:$B$104,$A15)) -> 2 | H15: =IF($A15="","",IF(G15=0,"SIN COBERTURA","Cubierto")) -> Cubierto | J15: =IF($A15="","",IF(G15=0,"Sin casos",IF(COUNTIFS(Catalogo!$B$5:$B$104,$A15,Catalogo!$M$5:$M$104,"FALLIDO")>0,"Fallido",IF(COUNTIFS(Catalogo!$B$5:$B$104,$A15,Catalogo!$M$5:$M$104,"APROBADO")=G15,"Aprobado","Pendiente")))) -> Pendiente
A16: =IF(Requisitos!A16="","",Requisitos!A16) -> RF-12 | B16: =IF($A16="","",Requisitos!B16) -> Ejecutar promedio móvil ponderado | C16: =IF($A16="","",Requisitos!C16) -> Pronóstico | D16: =IF($A16="","",Requisitos!D16) -> Funcional | E16: =IF($A16="","",Requisitos!E16) -> Alta | G16: =IF($A16="","",COUNTIF(Catalogo!$B$5:$B$104,$A16)) -> 1 | H16: =IF($A16="","",IF(G16=0,"SIN COBERTURA","Cubierto")) -> Cubierto | J16: =IF($A16="","",IF(G16=0,"Sin casos",IF(COUNTIFS(Catalogo!$B$5:$B$104,$A16,Catalogo!$M$5:$M$104,"FALLIDO")>0,"Fallido",IF(COUNTIFS(Catalogo!$B$5:$B$104,$A16,Catalogo!$M$5:$M$104,"APROBADO")=G16,"Aprobado","Pendiente")))) -> Pendiente
... A60: =IF(Requisitos!A60="","",Requisitos!A60) | B60: =IF($A60="","",Requisitos!B60) | C60: =IF($A60="","",Requisitos!C60) | D60: =IF($A60="","",Requisitos!D60) | E60: =IF($A60="","",Requisitos!E60) | G60: =IF($A60="","",COUNTIF(Catalogo!$B$5:$B$104,$A60)) | H60: =IF($A60="","",IF(G60=0,"SIN COBERTURA","Cubierto")) | J60: =IF($A60="","",IF(G60=0,"Sin casos",IF(COUNTIFS(Catalogo!$B$5:$B$104,$A60,Catalogo!$M$5:$M$104,"FALLIDO")>0,"Fallido",IF(COUNTIFS(Catalogo!$B$5:$B$104,$A60,Catalogo!$M$5:$M$104,"APROBADO")=G60,"Aprobado","Pendiente"))))
A62: En tu entrega no puede quedar ningún requisito funcional SIN COBERTURA.

Sheet Cobertura
A1: Resumen de cobertura (se calcula solo)
A2: No escribas aquí. Sirve para revisar tu entrega antes de enviarla.
A4: Indicador | B4: Valor
A5: Total de requisitos | B5: =COUNTA(Requisitos!A5:A60) -> 41
A6: Requisitos con al menos un caso | B6: =COUNTIF(Matriz!G5:G60,">0") -> 41
A7: % de requisitos cubiertos | B7: =IF(B5=0,0,B6/B5) -> 1
A8: Requisitos sin cobertura | B8: =B5-B6 -> 0
A9: Casos de prueba totales | B9: =COUNTA(Catalogo!A5:A104) -> 45
A10: Casos de verificación numérica | B10: =COUNTIF(Catalogo!E5:E104,"Verificación numérica") -> 10
A11: Casos "huérfanos" (requisito inexistente) | B11: {=SUMPRODUCT((Catalogo!B5:B104<>"")*(COUNTIF(Requisitos!A5:A60,Catalogo!B5:B104)=0))} -> 0
A12: ¿Mínimo 20 casos? | B12: =IF(B9>=20,"CUMPLE","FALTAN "&(20-B9)) -> CUMPLE
A13: ¿Mínimo 8 casos de verificación numérica? | B13: =IF(B10>=8,"CUMPLE","FALTAN "&(8-B10)) -> CUMPLE
A14: ¿100 % de requisitos con caso de prueba? | B14: =IF(B5=0,"SIN DATOS",IF(B8=0,"CUMPLE","FALTAN "&B8&" REQUISITO(S)")) -> CUMPLE
A17: Módulo | B17: Requisitos | C17: Con caso | D17: % cubierto
A18: Gestión de datos | B18: =COUNTIF(Requisitos!$C$5:$C$60,A18) -> 7 | C18: =COUNTIFS(Matriz!$C$5:$C$60,A18,Matriz!$G$5:$G$60,">0") -> 7 | D18: =IF(B18=0,"",C18/B18) -> 1
A19: Pronóstico | B19: =COUNTIF(Requisitos!$C$5:$C$60,A19) -> 14 | C19: =COUNTIFS(Matriz!$C$5:$C$60,A19,Matriz!$G$5:$G$60,">0") -> 14 | D19: =IF(B19=0,"",C19/B19) -> 1
A20: Indicadores y reportes | B20: =COUNTIF(Requisitos!$C$5:$C$60,A20) -> 6 | C20: =COUNTIFS(Matriz!$C$5:$C$60,A20,Matriz!$G$5:$G$60,">0") -> 6 | D20: =IF(B20=0,"",C20/B20) -> 1
A21: Autenticación y roles | B21: =COUNTIF(Requisitos!$C$5:$C$60,A21) -> 6 | C21: =COUNTIFS(Matriz!$C$5:$C$60,A21,Matriz!$G$5:$G$60,">0") -> 6 | D21: =IF(B21=0,"",C21/B21) -> 1
A22: Transversal | B22: =COUNTIF(Requisitos!$C$5:$C$60,A22) -> 8 | C22: =COUNTIFS(Matriz!$C$5:$C$60,A22,Matriz!$G$5:$G$60,">0") -> 8 | D22: =IF(B22=0,"",C22/B22) -> 1
A25: Veredicto de los casos | B25: Cantidad
A26: PENDIENTE | B26: =COUNTIF(Catalogo!$M$5:$M$104,A26) -> 45
A27: APROBADO | B27: =COUNTIF(Catalogo!$M$5:$M$104,A27) -> 0
A28: FALLIDO | B28: =COUNTIF(Catalogo!$M$5:$M$104,A28) -> 0
A29: BLOQUEADO | B29: =COUNTIF(Catalogo!$M$5:$M$104,A29) -> 0

Sheet Riesgos
A1: Matriz de riesgos (sección 7 del plan maestro)
A2: Exposición = probabilidad × impacto (escala 1 a 5). Nivel: Alto ≥ 15 · Medio 8–14 · Bajo < 8. Las pruebas se priorizan por el nivel de riesgo.
A4: ID | B4: Riesgo | C4: Módulo | D4: Tipo | E4: Probabilidad (1-5) | F4: Impacto (1-5) | G4: Exposición | H4: Nivel | I4: Estrategia de prueba / mitigación | J4: Casos relacionados | K4: Estado
A5: R-01 | B5: MAPE indeterminado o error cuando la demanda real es 0 | C5: Pronóstico | D5: Producto | E5: 4 | F5: 5 | G5: =IF(OR(E5="",F5=""),"",E5*F5) -> 20 | H5: =IF(G5="","",IF(G5>=15,"Alto",IF(G5>=8,"Medio","Bajo"))) -> Alto | I5: Probar valores límite en demanda 0, verificando exclusión del período y alerta informativa | J5: CP-009, CP-028 | K5: Pendiente
A6: R-02 | B6: Discrepancia en pronósticos frente al cálculo de referencia | C6: Pronóstico | D6: Producto | E6: 3 | F6: 5 | G6: =IF(OR(E6="",F6=""),"",E6*F6) -> 15 | H6: =IF(G6="","",IF(G6>=15,"Alto",IF(G6>=8,"Medio","Bajo"))) -> Alto | I6: Pruebas de verificación numérica comparando resultados con la hoja Calculo_Referencia | J6: CP-001 a CP-006 | K6: Pendiente
A7: R-03 | B7: Bypass de permisos por rol (respuestas sin HTTP 403) | C7: Autenticación y roles | D7: Producto | E7: 3 | F7: 5 | G7: =IF(OR(E7="",F7=""),"",E7*F7) -> 15 | H7: =IF(G7="","",IF(G7>=15,"Alto",IF(G7>=8,"Medio","Bajo"))) -> Alto | I7: Pruebas de integración de la API cruzando los cuatro roles contra endpoints restringidos | J7: CP-013 | K7: Pendiente
A8: R-04 | B8: Retraso o discrepancia en el Excel de referencia de Producción | C8: Transversal | D8: Proyecto | E8: 3 | F8: 5 | G8: =IF(OR(E8="",F8=""),"",E8*F8) -> 15 | H8: =IF(G8="","",IF(G8>=15,"Alto",IF(G8>=8,"Medio","Bajo"))) -> Alto | I8: Usar la serie sintética CAF-500 de respaldo para validar la lógica y pedir firma del Anexo B | J8: CP-001 a CP-010 | K8: Pendiente
A9: R-05 | B9: Tiempo de respuesta elevado en cálculo masivo | C9: Pronóstico | D9: Producto | E9: 3 | F9: 4 | G9: =IF(OR(E9="",F9=""),"",E9*F9) -> 12 | H9: =IF(G9="","",IF(G9>=15,"Alto",IF(G9>=8,"Medio","Bajo"))) -> Medio | I9: Pruebas de carga y rendimiento con k6 simulando ejecuciones concurrentes | J9: CP-034 | K9: Pendiente
A10: R-06 | B10: Pérdida de la serie original al imputar faltantes/atípicos | C10: Gestión de datos | D10: Producto | E10: 2 | F10: 5 | G10: =IF(OR(E10="",F10=""),"",E10*F10) -> 10 | H10: =IF(G10="","",IF(G10>=15,"Alto",IF(G10>=8,"Medio","Bajo"))) -> Medio | I10: Verificar que en la base de datos persista el dato original con su bandera de modificación | J10: CP-017, CP-025 | K10: Pendiente
A11: R-07 | B11: Aceptación de archivos CSV con formato corrupto | C11: Gestión de datos | D11: Producto | E11: 3 | F11: 3 | G11: =IF(OR(E11="",F11=""),"",E11*F11) -> 9 | H11: =IF(G11="","",IF(G11>=15,"Alto",IF(G11>=8,"Medio","Bajo"))) -> Medio | I11: Probar carga masiva con archivos corruptos, verificando el rechazo e informe de filas inválidas | J11: CP-016 | K11: Pendiente
A12: R-08 | B12: Fallo en la generación de reportes PDF/Excel | C12: Indicadores y reportes | D12: Producto | E12: 2 | F12: 4 | G12: =IF(OR(E12="",F12=""),"",E12*F12) -> 8 | H12: =IF(G12="","",IF(G12>=15,"Alto",IF(G12>=8,"Medio","Bajo"))) -> Medio | I12: Descargar reportes PDF/XLSX y comparar automáticamente los valores generados contra pantalla | J12: CP-030 | K12: Pendiente
A13: R-09 | B13: Indisponibilidad del ambiente Docker / BD de pruebas | C13: Transversal | D13: Proyecto | E13: 2 | F13: 4 | G13: =IF(OR(E13="",F13=""),"",E13*F13) -> 8 | H13: =IF(G13="","",IF(G13>=15,"Alto",IF(G13>=8,"Medio","Bajo"))) -> Medio | I13: Despliegue automatizado con Docker Compose y pipelines en GitHub Actions para reabrir en 1 comando | J13: CP-035 | K13: Pendiente
A14: R-10 | B14: Carga inicial de tableros supera los 2 segundos | C14: Indicadores y reportes | D14: Producto | E14: 2 | F14: 4 | G14: =IF(OR(E14="",F14=""),"",E14*F14) -> 8 | H14: =IF(G14="","",IF(G14>=15,"Alto",IF(G14>=8,"Medio","Bajo"))) -> Medio | I14: Medir latencias de carga inicial del dashboard y evaluar paginación / caché de datos | J14: CP-026, CP-034 | K14: Pendiente
A15: R-11 | B15: Umbrales de alerta de desviación no se activan | C15: Indicadores y reportes | D15: Producto | E15: 2 | F15: 3 | G15: =IF(OR(E15="",F15=""),"",E15*F15) -> 6 | H15: =IF(G15="","",IF(G15>=15,"Alto",IF(G15>=8,"Medio","Bajo"))) -> Bajo | I15: Configurar umbrales límite e ingresar series con alto error para validar el disparo de alertas | J15: CP-029 | K15: Pendiente
A16: R-12 | B16: Registro de duplicados en producto-período | C16: Gestión de datos | D16: Producto | E16: 2 | F16: 3 | G16: =IF(OR(E16="",F16=""),"",E16*F16) -> 6 | H16: =IF(G16="","",IF(G16>=15,"Alto",IF(G16>=8,"Medio","Bajo"))) -> Bajo | I16: Intentar ingresar un registro manual con mismo producto y período, verificando la restricción de BD | J16: CP-015 | K16: Pendiente
... A24: R-20 | B24: Fallo en la auditoría de acciones críticas por usuario/fecha | C24: Autenticación y roles | D24: Producto | E24: 1 | F24: 3 | G24: =IF(OR(E24="",F24=""),"",E24*F24) -> 3 | H24: =IF(G24="","",IF(G24>=15,"Alto",IF(G24>=8,"Medio","Bajo"))) -> Bajo | I24: Ejecutar operaciones como carga masiva o cambio de rol y consultar el log del sistema | J24: CP-025 | K24: Pendiente
G25: =IF(OR(E25="",F25=""),"",E25*F25) | H25: =IF(G25="","",IF(G25>=15,"Alto",IF(G25>=8,"Medio","Bajo")))
G26: =IF(OR(E26="",F26=""),"",E26*F26) | H26: =IF(G26="","",IF(G26>=15,"Alto",IF(G26>=8,"Medio","Bajo")))
G27: =IF(OR(E27="",F27=""),"",E27*F27) | H27: =IF(G27="","",IF(G27>=15,"Alto",IF(G27>=8,"Medio","Bajo")))
G28: =IF(OR(E28="",F28=""),"",E28*F28) | H28: =IF(G28="","",IF(G28>=15,"Alto",IF(G28>=8,"Medio","Bajo")))
G29: =IF(OR(E29="",F29=""),"",E29*F29) | H29: =IF(G29="","",IF(G29>=15,"Alto",IF(G29>=8,"Medio","Bajo")))
G30: =IF(OR(E30="",F30=""),"",E30*F30) | H30: =IF(G30="","",IF(G30>=15,"Alto",IF(G30>=8,"Medio","Bajo")))
G31: =IF(OR(E31="",F31=""),"",E31*F31) | H31: =IF(G31="","",IF(G31>=15,"Alto",IF(G31>=8,"Medio","Bajo")))
G32: =IF(OR(E32="",F32=""),"",E32*F32) | H32: =IF(G32="","",IF(G32>=15,"Alto",IF(G32>=8,"Medio","Bajo")))
G33: =IF(OR(E33="",F33=""),"",E33*F33) | H33: =IF(G33="","",IF(G33>=15,"Alto",IF(G33>=8,"Medio","Bajo")))
G34: =IF(OR(E34="",F34=""),"",E34*F34) | H34: =IF(G34="","",IF(G34>=15,"Alto",IF(G34>=8,"Medio","Bajo")))
G35: =IF(OR(E35="",F35=""),"",E35*F35) | H35: =IF(G35="","",IF(G35>=15,"Alto",IF(G35>=8,"Medio","Bajo")))
G36: =IF(OR(E36="",F36=""),"",E36*F36) | H36: =IF(G36="","",IF(G36>=15,"Alto",IF(G36>=8,"Medio","Bajo")))
... G44: =IF(OR(E44="",F44=""),"",E44*F44) | H44: =IF(G44="","",IF(G44>=15,"Alto",IF(G44>=8,"Medio","Bajo")))

Sheet Listas
A1: Módulo | B1: Tipo | C1: Prioridad | D1: Nivel | E1: Técnica | F1: Veredicto | G1: Tipo de riesgo | H1: Escala 1-5
A2: Gestión de datos | B2: Funcional | C2: Alta | D2: Unitaria | E2: Verificación numérica | F2: PENDIENTE | G2: Producto | H2: 1
